import { describe, it, expect, vi, beforeEach, afterEach } from "vitest";
import { LastWinsAndCancelsPrevious } from "../src";

const wait = (ms: number) => new Promise((r) => setTimeout(r, ms));

/**
 *
 * Больше тестов что queue.result сетиться только КОГДА запуститься task, иначе - undefined (особенно касается когда debounce/throttle с trailing без leading)
 * Также проверить что после завершения окна сетиться обратно в undefined для разных сочетаний trailing/leading/both
 * Также сделать тесты на кейс когда вызов run() откладывается (trailing debounce/throttle) и он должен НЕ сразу вернуть undefined, а только когда станет ясно что эту таску не вызовут, ну или наоборот - если вызовут - то вернуть значение
 */

describe("LastWinsAndCancelsPrevious", () => {
  it("resolves the result of a single task", async () => {
    const queue = new LastWinsAndCancelsPrevious<number>();
    expect(queue.result).toBeUndefined();
    const runResult = queue.run(async () => 42);
    expect(queue.result).not.toBeUndefined();
    const result = queue.result;
    expect(await runResult).toBe(42);
    expect(await result).toBe(42);
  });

  it("cancels the previous task when a new one is started", async () => {
    const queue = new LastWinsAndCancelsPrevious<number>();
    expect(queue.result).toBeUndefined();
    let firstAborted = false;
    const first = queue.run(async (signal) => {
      return new Promise<number>((resolve) => {
        signal.addEventListener("abort", () => {
          firstAborted = true;
          resolve(-1);
        });
        setTimeout(() => resolve(1), 100);
      });
    });
    const result = queue.result;
    expect(result).not.toBeUndefined();
    const second = queue.run(async () => 2);
    expect(queue.result).toBe(result);
    expect(await second).toBe(2);
    expect(await first).toBe(-1);
    expect(firstAborted).toBe(true);
    expect(await result).toBe(2);
  });

  it("run returns undefined when the task is cancelled", async () => {
    const queue = new LastWinsAndCancelsPrevious<number | undefined>();
    expect(queue.result).toBeUndefined();
    const first = queue.run(async (signal) => {
      return new Promise<number | undefined>((resolve) => {
        signal.addEventListener("abort", () => resolve(undefined));
        setTimeout(() => resolve(1), 100);
      });
    });
    const result = queue.result;
    expect(result).not.toBeUndefined();
    const second = queue.run(async () => 2); // отменяет первую
    expect(queue.result).toBe(result);
    expect(await first).toBeUndefined();
    expect(await second).toBe(2);
    expect(await result).toBe(2);
  });

  it("result resolves only with the last task", async () => {
    const queue = new LastWinsAndCancelsPrevious<number>();
    expect(queue.result).toBeUndefined();
    queue.run(async () => 1);
    const result = queue.result;
    expect(queue.result).toBe(result);
    queue.run(async () => 2);
    expect(queue.result).toBe(result);
    const last = queue.run(async () => 3);
    expect(await last).toBe(3);
    expect(await result).toBe(3);
  });

  it("old tasks without AbortSignal finish, but do not affect result", async () => {
    const queue = new LastWinsAndCancelsPrevious<number>();
    expect(queue.result).toBeUndefined();
    let finished = false;
    const first = queue.run(async () => {
      await new Promise((r) => setTimeout(() => r("first"), 100));
      finished = true;
      return 1;
    });
    const result = queue.result;
    expect(result).not.toBeUndefined();
    const last = queue.run(async () => 2);
    expect(queue.result).toBe(result);
    await wait(100);
    expect(await last).toBe(2);
    expect(await result).toBe(2);
    expect(await first).toBe(1); // Should be undefined, since the task was cancelled
    expect(finished).toBe(true);
  });

  it("an error in the task leads to result rejection", async () => {
    const queue = new LastWinsAndCancelsPrevious<number>();
    expect(queue.result).toBeUndefined();
    const error = new Error("fail");
    const task = queue.run(async () => {
      throw error;
    });
    const result = queue.result;
    expect(result).not.toBeUndefined();
    await expect(task).rejects.toThrow("fail");
    await expect(result).rejects.toThrow("fail");
  });

  it("first task fails BEFORE second completes — result = task2, task1 rejects", async () => {
    const queue = new LastWinsAndCancelsPrevious<number>();
    let reject1: (e: any) => void, resolve2: (v: number) => void;
    const error1 = new Error("fail1");
    const task1 = queue.run(
      () =>
        new Promise<number>((_, rej) => {
          reject1 = rej;
        })
    );
    const resultPromise = queue.result;
    const task2 = queue.run(
      () =>
        new Promise<number>((res) => {
          resolve2 = res;
        })
    );
    reject1!(error1); // First task fails immediately
    resolve2!(42); // Second completes after
    expect(await task2).toBe(42);
    expect(await resultPromise).toBe(42);
    await expect(task1).rejects.toThrow("fail1");
  });

  it("first task fails AFTER second completes — result = task2, task1 rejects", async () => {
    const queue = new LastWinsAndCancelsPrevious<number>();
    let reject1: (e: any) => void, resolve2: (v: number) => void;
    const error1 = new Error("fail1");
    const task1 = queue.run(
      () =>
        new Promise<number>((_, rej) => {
          reject1 = rej;
        })
    );
    const resultPromise = queue.result;
    const task2 = queue.run(
      () =>
        new Promise<number>((res) => {
          resolve2 = res;
        })
    );
    resolve2!(42); // Second completes first
    reject1!(error1); // First task fails after
    expect(await task2).toBe(42);
    expect(await resultPromise).toBe(42);
    await expect(task1).rejects.toThrow("fail1");
  });

  it("if the first task failed but was cancelled by the second — result = task2, task1 rejects", async () => {
    const queue = new LastWinsAndCancelsPrevious<number>();
    const error1 = new Error("fail1");
    let task1Reject: (e: any) => void;
    const task1 = queue.run(
      () =>
        new Promise<number>((_, reject) => {
          task1Reject = reject;
        })
    );
    task1
      .then((v) => console.log("🚀 ~ it ~ v:", v))
      .catch((e) => console.log("🚀 ~ it ~ e:", e));
    const resultPromise = queue.result;
    // Start the second task, which completes successfully
    const task2 = queue.run(async () => 42);
    expect(resultPromise).toBe(queue.result);
    // First task fails with error, but is already cancelled
    task1Reject!(error1);
    expect(queue.result).toBe(resultPromise);
    console.log("🚀 ~ it ~ task1:", task1);
    expect(await task2).toBe(42);
    expect(await resultPromise).toBe(42);
    await expect(task1).rejects.toThrow("fail1");
  });

  it("second task fails BEFORE first completes — result and task2 reject, task1 success", async () => {
    const queue = new LastWinsAndCancelsPrevious<number>();
    let resolve1: (v: number) => void;
    const error2 = new Error("fail2");
    const task1 = queue.run(
      () =>
        new Promise<number>((res) => {
          resolve1 = res;
        })
    );
    const resultPromise = queue.result;
    const task2 = queue.run(
      () =>
        new Promise<number>((_, rej) => {
          rej(error2);
        })
    );
    // Second task fails first
    await expect(task2).rejects.toThrow("fail2");
    resolve1!(1); // First task completes after
    expect(await task1).toBe(1);
    await expect(resultPromise).rejects.toThrow("fail2");
  });

  it("second task fails AFTER first completes — result and task2 reject, task1 success", async () => {
    const queue = new LastWinsAndCancelsPrevious<number>();
    let resolve1: (v: number) => void, reject2: (e: any) => void;
    const error2 = new Error("fail2");
    const task1 = queue.run(
      () =>
        new Promise<number>((res) => {
          resolve1 = res;
        })
    );
    const resultPromise = queue.result;
    const task2 = queue.run(
      () =>
        new Promise<number>((_, rej) => {
          reject2 = rej;
        })
    );
    resolve1!(1); // Первая задача завершается первой
    reject2!(error2); // Вторая падает после
    expect(await task1).toBe(1);
    await expect(task2).rejects.toThrow("fail2");
    await expect(resultPromise).rejects.toThrow("fail2");
  });

  it("if the second task fails — result and task2 reject, task1 success", async () => {
    const queue = new LastWinsAndCancelsPrevious<number>();
    const task1 = queue.run(async () => 1);
    const resultPromise = queue.result;
    // Вторая задача падает
    const error2 = new Error("fail2");
    const task2 = queue.run(async () => {
      throw error2;
    });
    expect(queue.result).toBe(resultPromise);
    expect(await task1).toBe(1);
    await expect(task2).rejects.toThrow("fail2");
    await expect(resultPromise).rejects.toThrow("fail2");
  });

  it("both tasks fail: first BEFORE second — result and task2 reject, task1 rejects", async () => {
    const queue = new LastWinsAndCancelsPrevious<number>();
    let reject1: (e: any) => void, reject2: (e: any) => void;
    const error1 = new Error("fail1");
    const error2 = new Error("fail2");
    const task1 = queue.run(
      () =>
        new Promise<number>((_, rej) => {
          reject1 = rej;
        })
    );
    const resultPromise = queue.result;
    const task2 = queue.run(
      () =>
        new Promise<number>((_, rej) => {
          reject2 = rej;
        })
    );
    reject1!(error1); // First fails first
    reject2!(error2); // Вторая падает после
    await expect(task1).rejects.toThrow("fail1");
    await expect(task2).rejects.toThrow("fail2");
    await expect(resultPromise).rejects.toThrow("fail2");
  });

  it("both tasks fail: second BEFORE first — result and task2 reject, task1 rejects", async () => {
    const queue = new LastWinsAndCancelsPrevious<number>();
    let reject1: (e: any) => void, reject2: (e: any) => void;
    const error1 = new Error("fail1");
    const error2 = new Error("fail2");
    const task1 = queue.run(
      () =>
        new Promise<number>((_, rej) => {
          reject1 = rej;
        })
    );
    const resultPromise = queue.result;
    const task2 = queue.run(
      () =>
        new Promise<number>((_, rej) => {
          reject2 = rej;
        })
    );
    reject2!(error2); // Second fails first
    reject1!(error1); // First fails after
    await expect(task1).rejects.toThrow("fail1");
    await expect(task2).rejects.toThrow("fail2");
    await expect(resultPromise).rejects.toThrow("fail2");
  });

  it("if both tasks failed — result and task2 reject, task1 rejects", async () => {
    const queue = new LastWinsAndCancelsPrevious<number>();
    const error1 = new Error("fail1");
    const error2 = new Error("fail2");
    const task1 = queue.run(async () => {
      throw error1;
    });
    const resultPromise = queue.result;
    const task2 = queue.run(async () => {
      throw error2;
    });
    expect(queue.result).toBe(resultPromise);
    await expect(task1).rejects.toThrow("fail1");
    await expect(task2).rejects.toThrow("fail2");
    await expect(resultPromise).rejects.toThrow("fail2");
  });

  it("concurrent: only the result of the last task goes to result", async () => {
    const queue = new LastWinsAndCancelsPrevious<number>();
    expect(queue.result).toBeUndefined();
    let resolve1: (v: number) => void;
    let resolve2: (v: number) => void;
    let resolve3: (v: number) => void;
    const p1 = queue.run(
      () =>
        new Promise<number>((r) => {
          resolve1 = r;
        })
    );
    const result = queue.result;
    expect(result).not.toBeUndefined();
    const p2 = queue.run(
      () =>
        new Promise<number>((r) => {
          resolve2 = r;
        })
    );
    expect(queue.result).toBe(result);
    const p3 = queue.run(
      () =>
        new Promise<number>((r) => {
          resolve3 = r;
        })
    );
    expect(queue.result).toBe(result);
    resolve3!(33);
    expect(await p3).toBe(33);
    resolve1!(11);
    resolve2!(22);
    expect(await p1).toBe(11);
    expect(await p2).toBe(22);
    expect(await result).toBe(33);
  });
});

// --- Result consistency tests ---
describe("result consistency", () => {
  it("result does not resolve until the last run is finished (no debounce/throttle)", async () => {
    const queue = new LastWinsAndCancelsPrevious<number>();
    expect(queue.result).toBeUndefined();
    let resolve1: (v: number) => void;
    let resolve2: (v: number) => void;
    let resultResolved = false;
    const p1 = queue.run(
      () =>
        new Promise<number>((r) => {
          resolve1 = r;
        })
    );
    const result = queue.result;
    expect(result).not.toBeUndefined();
    const p2 = queue.run(
      () =>
        new Promise<number>((r) => {
          resolve2 = r;
        })
    );
    expect(queue.result).toBe(result);
    const resultPromise = queue.result!;
    resultPromise.then(() => {
      resultResolved = true;
    });
    // Завершаем первую задачу — result не должен резолвиться
    expect(resultResolved).toBe(false);
    resolve1!(1);
    await Promise.resolve();
    expect(resultResolved).toBe(false);
    // Complete the second (last) task — now result should resolve
    resolve2!(2);
    await resultPromise;
    expect(resultResolved).toBe(true);
    expect(await resultPromise).toBe(2);
  });

  it("result does not resolve until the last run is executed (debounce trailing)", async () => {
    const queue = new LastWinsAndCancelsPrevious<number>({ debounceMs: 300 });
    let resolveLast: (v: number) => void;
    let resultResolved = false;
    expect(queue.result).toBeUndefined();
    queue.run(() => new Promise<number>((r) => {}));
    expect(queue.result).toBeUndefined();
    queue.run(() => new Promise<number>((r) => {}));
    expect(queue.result).toBeUndefined();
    const lastPromise = queue.run(
      () =>
        new Promise<number>((r) => {
          resolveLast = r;
        })
    );
    expect(queue.result).toBeUndefined();
    await wait(400);
    const result = queue.result;
    expect(result).not.toBeUndefined();
    result!.then(() => {
      resultResolved = true;
    });
    // Пока задача не завершена
    expect(resultResolved).toBe(false);
    // Завершаем задачу
    resolveLast!(42);
    await wait(50);
    expect(resultResolved).toBe(true);
    expect(await result).toBe(42);
    //тот самый случай, когда мы не отследили что таска была отложена и подумали что ее скипнул дебаунс и вернули undefined а он не скипал ее а просто отложил
    expect(await lastPromise).toBe(42);
  });

  it("result does not resolve until the last run is executed (throttle leading)", async () => {
    const queue = new LastWinsAndCancelsPrevious<number>({
      throttleMs: 300,
      edge: "leading",
    });
    expect(queue.result).toBeUndefined();
    let resolve1: (v: number) => void;
    let resolve2: (v: number) => void;
    let resultResolved = false;
    const p1 = queue.run(
      () =>
        new Promise<number>((r) => {
          resolve1 = r;
        })
    );
    const result = queue.result;
    expect(result).not.toBeUndefined();
    result!.then(() => {
      resultResolved = true;
    });
    await wait(350);
    const p2 = queue.run(
      () =>
        new Promise<number>((r) => {
          resolve2 = r;
        })
    );
    expect(queue.result).toBe(result);
    // Complete the first task — result should not resolve, because throttle did not allow the second
    resolve1!(1);
    await Promise.resolve();
    expect(resultResolved).toBe(false);
    // Now complete the second (which should not have been called)
    resolve2!(2);
    expect(await p1).toBe(1);
    expect(await p2).toBe(2);
    expect(await result).toBe(2);
  });

  it("result does not resolve until trailing is executed (throttle trailing)", async () => {
    const queue = new LastWinsAndCancelsPrevious<number>({
      throttleMs: 300,
      edge: "trailing",
    });
    expect(queue.result).toBeUndefined();
    let resolveLast: (v: number) => void;
    let resultResolved = false;
    queue.run(() => new Promise<number>((r) => {}));
    expect(queue.result).toBeUndefined();
    queue.run(() => new Promise<number>((r) => {}));
    expect(queue.result).toBeUndefined();
    const lastPromise = queue.run(
      () =>
        new Promise<number>((r) => {
          resolveLast = r;
        })
    );
    expect(queue.result).toBeUndefined();
    await wait(350);
    const result = queue.result;
    expect(result).not.toBeUndefined();
    result!.then(() => {
      resultResolved = true;
    });
    expect(resultResolved).toBe(false);
    resolveLast!(99);
    await lastPromise;
    expect(await result).toBe(99);
    expect(resultResolved).toBe(true);
    //тот самый случай, когда мы не отследили что таска была отложена и подумали что ее скипнул дебаунс и вернули undefined а он не скипал ее а просто отложил
    expect(await lastPromise).toBe(99);
  });
});

describe("LastWinsAndCancelsPrevious — debounce/throttle behavior", () => {
  const makeTask =
    (value: number, log: number[], delayMs?: number) =>
    async (signal: AbortSignal) => {
      log.push(value);
      if (delayMs) {
        await wait(delayMs);
      }
      return value;
    };

  it("debounce trailing=true (по умолчанию): вызывает только после паузы", async () => {
    const log: number[] = [];
    const queue = new LastWinsAndCancelsPrevious<number>({ debounceMs: 300 });

    const r1 = queue.run(makeTask(1, log));
    expect(queue.result).toBeUndefined();
    await wait(100);
    expect(queue.result).toBeUndefined();
    const r2 = queue.run(makeTask(2, log));
    expect(queue.result).toBeUndefined();
    await wait(100);
    expect(queue.result).toBeUndefined();
    const r3 = queue.run(makeTask(3, log, 400));
    expect(queue.result).toBeUndefined();
    await wait(400);
    const result = queue.result;
    expect(log).toEqual([3]);
    expect(await result).toBe(3);
    expect(await r1).toBeUndefined();
    expect(await r2).toBeUndefined();
    //тот самый случай, когда мы не отследили что таска была отложена и подумали что ее скипнул дебаунс и вернули undefined а он не скипал ее а просто отложил
    expect(await r3).toBe(3);
    expect(queue.result).toBeUndefined();
  });

  it("debounce leading=true: вызывает сразу, не в конце", async () => {
    const log: number[] = [];
    const queue = new LastWinsAndCancelsPrevious<number>({
      debounceMs: 300,
      edge: "leading",
    });
    expect(queue.result).toBeUndefined();
    const r1 = queue.run(makeTask(1, log));
    expect(queue.result).not.toBeUndefined();
    const result1 = queue.result;
    await wait(100);
    const r2 = queue.run(makeTask(2, log));
    await wait(1000);
    expect(queue.result).toBeUndefined();
    const r3 = queue.run(makeTask(3, log));
    const result2 = queue.result;
    await wait(100);
    await Promise.all([r1, r2, r3]);
    expect(await r1).toBe(1);
    expect(await r2).toBeUndefined();
    expect(await r3).toBe(3);
    expect(log).toEqual([1, 3]);
    expect(await result1).toBe(1);
    expect(queue.result).toBeUndefined();
    expect(await result2).toBe(3);
  });

  it("debounce leading + trailing: calls twice — at start and end", async () => {
    const log: number[] = [];
    const queue = new LastWinsAndCancelsPrevious<number>({
      debounceMs: 300,
      edge: "both",
    });
    expect(queue.result).toBeUndefined();
    const r1 = queue.run(makeTask(1, log));
    const result1 = queue.result;
    expect(result1).not.toBeUndefined();
    await wait(100);
    const r2 = queue.run(makeTask(2, log));
    await wait(200);
    const r3 = queue.run(makeTask(3, log, 400));
    await wait(400);

    const result2 = queue.result;
    expect(log).toEqual([1, 3]);
    expect(await result1).toBe(1);
    expect(await r1).toBe(1);
    expect(await r2).toBeUndefined();
    expect(await result2).toBe(3);
    expect(queue.result).toBeUndefined();
    //тот самый случай, когда мы не отследили что таска была отложена и подумали что ее скипнул дебаунс и вернули undefined а он не скипал ее а просто отложил
    expect(await r3).toBe(3);
  });

  it("throttle leading=true: calls once per interval", async () => {
    const log: number[] = [];
    const queue = new LastWinsAndCancelsPrevious<number>({
      throttleMs: 300,
      edge: "leading",
    });

    expect(queue.result).toBeUndefined();
    const r1 = queue.run(makeTask(1, log));
    expect(queue.result).not.toBeUndefined();
    await wait(100);
    expect(queue.result).toBeUndefined();
    const r2 = queue.run(makeTask(2, log));
    expect(queue.result).toBeUndefined();
    await wait(200);
    expect(queue.result).toBeUndefined();
    await wait(400);
    expect(queue.result).toBeUndefined();
    const r3 = queue.run(makeTask(3, log, 400));
    const result = queue.result;
    expect(result).not.toBeUndefined();

    expect(log).toEqual([1, 3]);
    expect(await r1).toBe(1);
    expect(await r2).toBeUndefined();
    expect(await r3).toBe(3);
    expect(await result).toBe(3);
    expect(queue.result).toBeUndefined();
  });

  it("throttle trailing=true: calls at the end of interval", async () => {
    const log: number[] = [];
    const queue = new LastWinsAndCancelsPrevious<number>({
      throttleMs: 300,
      edge: "trailing",
    });

    expect(queue.result).toBeUndefined();
    const r1 = queue.run(makeTask(1, log));
    expect(queue.result).toBeUndefined();
    await wait(100);
    expect(queue.result).toBeUndefined();
    const r2 = queue.run(makeTask(2, log, 300));
    expect(queue.result).toBeUndefined();
    await wait(300);
    expect(queue.result).not.toBeUndefined();
    const r3 = queue.run(makeTask(3, log, 300));
    await wait(300);
    expect(queue.result).not.toBeUndefined();
    expect(await r1).toBeUndefined();
    //тот самый случай, когда мы не отследили что таска была отложена и подумали что ее скипнул дебаунс и вернули undefined а он не скипал ее а просто отложил
    expect(await r2).toBe(2);
    //тот самый случай, когда мы не отследили что таска была отложена и подумали что ее скипнул дебаунс и вернули undefined а он не скипал ее а просто отложил
    expect(await r3).toBe(3);
    expect(log).toEqual([2, 3]);
    expect(queue.result).toBeUndefined();
  });

  it("throttle leading + trailing: calls twice per interval", async () => {
    const log: number[] = [];
    const queue = new LastWinsAndCancelsPrevious<number>({
      throttleMs: 300,
      edge: "both",
    });

    expect(queue.result).toBeUndefined();
    const r1 = queue.run(makeTask(1, log));
    expect(queue.result).not.toBeUndefined();
    await wait(100);
    expect(queue.result).toBeUndefined();
    const r2 = queue.run(makeTask(2, log));
    expect(queue.result).toBeUndefined();
    await wait(300);
    expect(queue.result).toBeUndefined();
    const r3 = queue.run(makeTask(3, log));
    expect(queue.result).not.toBeUndefined();
    await wait(400);
    expect(queue.result).toBeUndefined();
    const r4 = queue.run(makeTask(4, log));
    expect(queue.result).not.toBeUndefined();
    const result = queue.result;
    expect(result).not.toBeUndefined();
    await wait(400);

    expect(await result).toBe(4);
    expect(await r1).toBe(1);
    //тот самый случай, когда мы не отследили что таска была отложена и подумали что ее скипнул дебаунс и вернули undefined а он не скипал ее а просто отложил
    expect(await r2).toBe(2);
    expect(await r3).toBe(3);
    expect(await r4).toBe(4);
    expect(await result).toBe(4);
    expect(log).toEqual([1, 2, 3, 4]);
  });
});

describe("LastWinsAndCancelsPrevious — hooks and abort", () => {
  it("calls onAborted when task is cancelled by new run", async () => {
    const onAborted = vi.fn();
    const queue = new LastWinsAndCancelsPrevious<number>();
    queue.onAborted(onAborted);
    let aborted = false;
    const first = queue.run(async (signal) => {
      return new Promise<number>((resolve) => {
        signal.addEventListener("abort", () => {
          aborted = true;
          resolve(-1);
        });
        setTimeout(() => resolve(1), 100);
      });
    });
    const second = queue.run(async () => 2);
    expect(await second).toBe(2);
    expect(await first).toBe(-1);
    expect(aborted).toBe(true);
    expect(onAborted).toHaveBeenCalledTimes(1);
    expect(onAborted.mock.calls[0][0]).toMatchObject({ aborted: true });
  });

  it("calls onAborted when abort() is called", async () => {
    const onAborted = vi.fn();
    const queue = new LastWinsAndCancelsPrevious<number>();
    queue.onAborted(onAborted);
    let aborted = false;
    const task = queue.run(async (signal) => {
      return new Promise<number>((resolve) => {
        signal.addEventListener("abort", () => {
          aborted = true;
          resolve(-1);
        });
        setTimeout(() => resolve(1), 100);
      });
    });
    queue.abort();
    expect(await task).toBe(-1);
    expect(aborted).toBe(true);
    expect(onAborted).toHaveBeenCalledTimes(1);
    expect(onAborted.mock.calls[0][0]).toMatchObject({ aborted: true });
  });

  it("calls onError when task throws", async () => {
    const onError = vi.fn();
    const queue = new LastWinsAndCancelsPrevious<number>();
    queue.onError(onError);
    const error = new Error("fail");
    const task = queue.run(async () => {
      throw error;
    });
    await expect(task).rejects.toThrow("fail");
    expect(onError).toHaveBeenCalledTimes(1);
    // После ошибки — isSeriesEnd === true
    expect(onError.mock.calls[0][0]).toMatchObject({
      error,
      isSeriesEnd: true,
    });
  });

  it("calls onComplete when task resolves", async () => {
    const onComplete = vi.fn();
    const queue = new LastWinsAndCancelsPrevious<number>();
    queue.onComplete(onComplete);
    const task = queue.run(async () => 42);
    expect(await task).toBe(42);
    expect(onComplete).toHaveBeenCalledTimes(1);
    // После успешного завершения — isSeriesEnd === true
    expect(onComplete.mock.calls[0][0]).toMatchObject({
      result: 42,
      isSeriesEnd: true,
    });
    // После успешного завершения — isSeriesEnd === true
    expect(onComplete.mock.calls[0][0]).toMatchObject({
      result: 42,
      isSeriesEnd: true,
    });
  });

  it("does not call hooks extra times (multiple aborts, errors, completes)", async () => {
    const onAborted = vi.fn();
    const onError = vi.fn();
    const onComplete = vi.fn();
    const queue = new LastWinsAndCancelsPrevious<number>();
    queue.onAborted(onAborted);
    queue.onError(onError);
    queue.onComplete(onComplete);
    // First: success
    await queue.run(async () => 1);
    expect(onAborted).toHaveBeenCalledTimes(0); // после первого run — не было отмен
    // Second: error
    await expect(
      queue.run(async () => {
        throw new Error("err");
      })
    ).rejects.toThrow("err");
    expect(onAborted).toHaveBeenCalledTimes(1); // 1. abort by new run
    expect(onAborted.mock.calls[0][0]).toMatchObject({ isSeriesEnd: false });
    // Third: abort by new run
    const t1 = queue.run(
      async (signal) =>
        new Promise<number>((resolve) => {
          signal.addEventListener("abort", () => resolve(-1));
          setTimeout(() => resolve(10), 100);
        })
    );
    expect(onAborted).toHaveBeenCalledTimes(2); // 2. abort by new run
    expect(onAborted.mock.calls[1][0]).toMatchObject({ isSeriesEnd: false });
    // 2. abort by new run — isSeriesEnd: false
    expect(onAborted.mock.calls[1][0]).toMatchObject({ isSeriesEnd: false });
    const t2 = queue.run(async () => 2);
    expect(onAborted).toHaveBeenCalledTimes(3); // 3. abort by new run
    expect(onAborted.mock.calls[2][0]).toMatchObject({ isSeriesEnd: false });
    // 3. abort by new run — isSeriesEnd: false
    expect(onAborted.mock.calls[2][0]).toMatchObject({ isSeriesEnd: false });
    await t1;
    await t2;
    // Fourth: abort by abort()
    const t3 = queue.run(
      async (signal) =>
        new Promise<number>((resolve) => {
          signal.addEventListener("abort", () => resolve(-1));
          setTimeout(() => resolve(3), 100);
        })
    );
    expect(onAborted).toHaveBeenCalledTimes(4); // 4. abort by abort()
    expect(onAborted.mock.calls[3][0]).toMatchObject({ isSeriesEnd: false });
    queue.abort();
    await t3;
    expect(onAborted).toHaveBeenCalledTimes(5); // 5. abort by abort()
    expect(onAborted.mock.calls[4][0]).toMatchObject({ isSeriesEnd: true });
    expect(onComplete).toHaveBeenCalledTimes(2);
    expect(onError).toHaveBeenCalledTimes(1);
    expect(onAborted).toHaveBeenCalledTimes(5);
  });

  it("does not break if hook throws", async () => {
    const onAborted = vi.fn(() => {
      throw new Error("hook fail");
    });
    const onError = vi.fn(() => {
      throw new Error("hook fail");
    });
    const onComplete = vi.fn(() => {
      throw new Error("hook fail");
    });
    const queue = new LastWinsAndCancelsPrevious<number>();
    queue.onAborted(onAborted);
    queue.onError(onError);
    queue.onComplete(onComplete);
    // onComplete throws, but task still resolves
    expect(await queue.run(async () => 1)).toBe(1);
    // onError throws, but task still rejects
    await expect(
      queue.run(async () => {
        throw new Error("err");
      })
    ).rejects.toThrow("err");
    // onAborted throws, but abort still works
    const t = queue.run(
      async (signal) =>
        new Promise<number>((resolve) => {
          signal.addEventListener("abort", () => resolve(-1));
          setTimeout(() => resolve(5), 100);
        })
    );
    queue.abort();
    expect(await t).toBe(-1);
  });

  it("abort() does nothing if no active task", () => {
    const onAborted = vi.fn();
    const queue = new LastWinsAndCancelsPrevious<number>();
    queue.onAborted(onAborted);
    queue.abort();
    expect(onAborted).not.toHaveBeenCalled();
  });
});
